<robot name = "2bot">
  
  <link name = "base_link">
    <visual name = "ground">
      <origin xyz = "0 0 0" rpy = "0 0 0"/>
      <geometry>
	<box size = "0 0 0"/>
      </geometry>
      <material name = "color0">
	<color rgba = "0 0 1 1"/>
      </material>
    </visual>
  </link>

  <link name = "post">
    <visual name = "post">
      <origin xyz = "0 0 .3" rpy = "0 0 0"/>
      <geometry>
	<cylinder radius = ".05" length = ".6"/>
      </geometry>
      <material name = "color0"/>
    </visual>
  </link>


  <link name = "arm1">
    <visual name = "arm1">
      <origin xyz = ".5 0 0" rpy = "0 0 0"/>
      <geometry>
	<box size = "1 .05 .05"/>
      </geometry>'
      <material name = "color1">
	<color rgba = ".3 .1 .1 1"/>
      </material>
    </visual>
  </link>

  <link name = "arm2">
    <visual name = "arm2">
      <origin xyz = ".5 0 -.05" rpy = "0 0 0"/>
      <geometry>
	<box size = "1 .05 .05"/>
      </geometry>'
      <material name = "color2">
	<color rgba = ".1 .1 .3 1"/>
      </material>
    </visual>
  </link>

  <link name = "pen">
    <visual name = "pen">
      <origin xyz = "0 0 -.275" rpy = "0 0 0"/>
      <geometry>
	<cylinder radius = ".005" length = ".45"/>
      </geometry>
      <material name = "color3">
	<color rgba = "1 1 1 1"/>
      </material>
    </visual>
  </link>

  <link name = "connector">
    <visual name = "connector">
      <origin xyz = "0 0 -.025" rpy = "0 0 0"/>
      <geometry>
	<cylinder radius = ".05" length = ".15"/>
      </geometry>
      <material name = "black">
	<color rgba = "0 0 0 1"/>
      </material>
    </visual>
  </link>
  
  <link name = "connector2">
    <visual name = "connector2">
      <origin xyz = "0 0 -.05" rpy = "0 0 0"/>
      <geometry>
	<cylinder radius = ".05" length = ".075"/>
      </geometry>
      <material name = "black">
	<color rgba = "0 0 0 1"/>
      </material>
    </visual>
  </link>

  <joint name = "j0" type = "fixed">
    <parent link = "base_link"/>
    <child link = "post"/>
    <origin xyz = "0 0 0"/>
  </joint>

  <joint name = "j1" type = "continuous">
    <parent link = "post"/>
    <child link = "arm1"/>
    <origin xyz = "0 0 .5"/>
    <axis xyz = "0 0 1"/>
  </joint>

  <joint name = "j2" type = "continuous">
    <parent link = "arm1"/>
    <child link = "arm2"/>
    <origin xyz = "1 0 0"/>
    <axis xyz = "0 0 1"/>
  </joint>

  <joint name = "j3" type = "fixed">
    <parent link = "arm2"/>
    <child link = "pen"/>
    <origin xyz = "1 0 0"/>
    <axis xyz = "0 0 1"/>
  </joint>
  
  <joint name = "j4" type = "fixed">
    <parent link = "arm1"/>
    <child link = "connector"/>
    <origin xyz = "1 0 0"/>
    <axis xyz = "0 0 1"/>
  </joint>

  <joint name = "j5" type = "fixed">
    <parent link = "arm2"/>
    <child link = "connector2"/>
    <origin xyz = "1 0 0"/>
    <axis xyz = "0 0 1"/>
  </joint>
  

</robot>
